Traceback (most recent call last):
  File "/home/mwess/.local/lib/python3.10/site-packages/jupyter_cache/executors/utils.py", line 58, in single_nb_execution
    executenb(
  File "/home/mwess/.local/lib/python3.10/site-packages/nbclient/client.py", line 1269, in execute
    return NotebookClient(nb=nb, resources=resources, km=km, **kwargs).execute()
  File "/home/mwess/.local/lib/python3.10/site-packages/nbclient/util.py", line 85, in wrapped
    return just_run(coro(*args, **kwargs))
  File "/home/mwess/.local/lib/python3.10/site-packages/nbclient/util.py", line 60, in just_run
    return loop.run_until_complete(coro)
  File "/usr/lib/python3.10/asyncio/base_events.py", line 649, in run_until_complete
    return future.result()
  File "/home/mwess/.local/lib/python3.10/site-packages/nbclient/client.py", line 707, in async_execute
    await self.async_execute_cell(
  File "/home/mwess/.local/lib/python3.10/site-packages/nbclient/client.py", line 1025, in async_execute_cell
    await self._check_raise_for_error(cell, cell_index, exec_reply)
  File "/home/mwess/.local/lib/python3.10/site-packages/nbclient/client.py", line 919, in _check_raise_for_error
    raise CellExecutionError.from_cell_and_msg(cell, exec_reply_content)
nbclient.exceptions.CellExecutionError: An error occurred while executing the following cell:
------------------
# import ngsolve and webgui
from ngsolve import *
from ngsolve.webgui import Draw

# draw the unit_square shape
Draw(unit_square.shape);
------------------

[0;31m---------------------------------------------------------------------------[0m
[0;31mNameError[0m                                 Traceback (most recent call last)
Input [0;32mIn [1][0m, in [0;36m<cell line: 6>[0;34m()[0m
[1;32m      3[0m [38;5;28;01mfrom[39;00m [38;5;21;01mngsolve[39;00m[38;5;21;01m.[39;00m[38;5;21;01mwebgui[39;00m [38;5;28;01mimport[39;00m Draw
[1;32m      5[0m [38;5;66;03m# draw the unit_square shape[39;00m
[0;32m----> 6[0m Draw([43munit_square[49m[38;5;241m.[39mshape)

[0;31mNameError[0m: name 'unit_square' is not defined
NameError: name 'unit_square' is not defined

